[2025-03-02T10:24:18.577+0000] {taskinstance.py:1159} INFO - Dependencies all met for dep_context=non-requeueable deps ti=<TaskInstance: new_messages.lda_model manual__2025-03-02T10:16:42.550264+00:00 [queued]>
[2025-03-02T10:24:18.595+0000] {taskinstance.py:1159} INFO - Dependencies all met for dep_context=requeueable deps ti=<TaskInstance: new_messages.lda_model manual__2025-03-02T10:16:42.550264+00:00 [queued]>
[2025-03-02T10:24:18.595+0000] {taskinstance.py:1361} INFO - Starting attempt 1 of 1
[2025-03-02T10:24:18.617+0000] {taskinstance.py:1382} INFO - Executing <Task(DockerOperator): lda_model> on 2025-03-02 10:16:42.550264+00:00
[2025-03-02T10:24:18.625+0000] {standard_task_runner.py:57} INFO - Started process 4459 to run task
[2025-03-02T10:24:18.631+0000] {standard_task_runner.py:84} INFO - Running: ['***', 'tasks', 'run', 'new_messages', 'lda_model', 'manual__2025-03-02T10:16:42.550264+00:00', '--job-id', '41', '--raw', '--subdir', 'DAGS_FOLDER/mess_cluster.py', '--cfg-path', '/tmp/tmpi_j8m0f8']
[2025-03-02T10:24:18.636+0000] {standard_task_runner.py:85} INFO - Job 41: Subtask lda_model
[2025-03-02T10:24:18.787+0000] {task_command.py:416} INFO - Running <TaskInstance: new_messages.lda_model manual__2025-03-02T10:16:42.550264+00:00 [running]> on host 0cbb564b3fd1
[2025-03-02T10:24:18.994+0000] {taskinstance.py:1662} INFO - Exporting env vars: AIRFLOW_CTX_DAG_OWNER='***' AIRFLOW_CTX_DAG_ID='new_messages' AIRFLOW_CTX_TASK_ID='lda_model' AIRFLOW_CTX_EXECUTION_DATE='2025-03-02T10:16:42.550264+00:00' AIRFLOW_CTX_TRY_NUMBER='1' AIRFLOW_CTX_DAG_RUN_ID='manual__2025-03-02T10:16:42.550264+00:00'
[2025-03-02T10:24:19.136+0000] {docker.py:367} INFO - Starting docker container from image model-train:latest
[2025-03-02T10:24:30.026+0000] {docker.py:438} INFO - INFO:root:Подгружаем данные
[2025-03-02T10:24:30.043+0000] {docker.py:438} INFO - INFO:root:Подгрузили
[2025-03-02T10:24:30.072+0000] {docker.py:438} INFO - Traceback (most recent call last):
[2025-03-02T10:24:30.084+0000] {docker.py:438} INFO -   File "/workdir/TrainLDA.py", line 33, in <module>
[2025-03-02T10:24:30.102+0000] {docker.py:438} INFO -     train()
[2025-03-02T10:24:30.111+0000] {docker.py:438} INFO -   File "/usr/local/lib/python3.12/site-packages/click/core.py", line 1161, in __call__
[2025-03-02T10:24:30.238+0000] {docker.py:438} INFO - return self.main(*args, **kwargs)
[2025-03-02T10:24:30.261+0000] {docker.py:438} INFO -            ^^^^^^^^^^^^^^^^^^^^^^^^^^
[2025-03-02T10:24:30.262+0000] {docker.py:438} INFO -   File "/usr/local/lib/python3.12/site-packages/click/core.py", line 1082, in main
[2025-03-02T10:24:30.263+0000] {docker.py:438} INFO -     rv = self.invoke(ctx)
[2025-03-02T10:24:30.267+0000] {docker.py:438} INFO -          ^^^^^^^^^^^^^^^^
[2025-03-02T10:24:30.276+0000] {docker.py:438} INFO -   File "/usr/local/lib/python3.12/site-packages/click/core.py", line 1443, in invoke
[2025-03-02T10:24:30.277+0000] {docker.py:438} INFO - return ctx.invoke(self.callback, **ctx.params)
[2025-03-02T10:24:30.289+0000] {docker.py:438} INFO -            ^^^^^^^^^^^^^^^^^^^^^^^^^^^^^^^^^^^^^^^
[2025-03-02T10:24:30.290+0000] {docker.py:438} INFO -   File "/usr/local/lib/python3.12/site-packages/click/core.py", line 788, in invoke
[2025-03-02T10:24:30.291+0000] {docker.py:438} INFO -     return __callback(*args, **kwargs)
[2025-03-02T10:24:30.292+0000] {docker.py:438} INFO -            ^^^^^^^^^^^^^^^^^^^^^^^^^^^
[2025-03-02T10:24:30.293+0000] {docker.py:438} INFO -   File "/workdir/TrainLDA.py", line 22, in train
[2025-03-02T10:24:30.294+0000] {docker.py:438} INFO -     dataset = count_vect.fit_transform(texts)
[2025-03-02T10:24:30.294+0000] {docker.py:438} INFO -               ^^^^^^^^^^^^^^^^^^^^^^^^^^^^^^^
[2025-03-02T10:24:30.306+0000] {docker.py:438} INFO -   File "/usr/local/lib/python3.12/site-packages/sklearn/base.py", line 1389, in wrapper
[2025-03-02T10:24:30.307+0000] {docker.py:438} INFO - return fit_method(estimator, *args, **kwargs)
[2025-03-02T10:24:30.309+0000] {docker.py:438} INFO -            ^^^^^^^^^^^^^^^^^^^^^^^^^^^^^^^^^^^^^^
[2025-03-02T10:24:30.310+0000] {docker.py:438} INFO -   File "/usr/local/lib/python3.12/site-packages/sklearn/feature_extraction/text.py", line 1376, in fit_transform
[2025-03-02T10:24:30.311+0000] {docker.py:438} INFO - vocabulary, X = self._count_vocab(raw_documents, self.fixed_vocabulary_)
[2025-03-02T10:24:30.312+0000] {docker.py:438} INFO -                     ^^^^^^^^^^^^^^^^^^^^^^^^^^^^^^^^^^^^^^^^^^^^^^^^^^^^^^^^
[2025-03-02T10:24:30.313+0000] {docker.py:438} INFO -   File "/usr/local/lib/python3.12/site-packages/sklearn/feature_extraction/text.py", line 1263, in _count_vocab
[2025-03-02T10:24:30.314+0000] {docker.py:438} INFO - for feature in analyze(doc):
[2025-03-02T10:24:30.315+0000] {docker.py:438} INFO -                    ^^^^^^^^^^^^
[2025-03-02T10:24:30.316+0000] {docker.py:438} INFO -   File "/usr/local/lib/python3.12/site-packages/sklearn/feature_extraction/text.py", line 99, in _analyze
[2025-03-02T10:24:30.316+0000] {docker.py:438} INFO - doc = decoder(doc)
[2025-03-02T10:24:30.317+0000] {docker.py:438} INFO -           ^^^^^^^^^^^^
[2025-03-02T10:24:30.318+0000] {docker.py:438} INFO -   File "/usr/local/lib/python3.12/site-packages/sklearn/feature_extraction/text.py", line 232, in decode
[2025-03-02T10:24:30.339+0000] {docker.py:438} INFO - raise ValueError(
[2025-03-02T10:24:30.349+0000] {docker.py:438} INFO - ValueError: np.nan is an invalid document, expected byte or unicode string.
[2025-03-02T10:24:31.063+0000] {taskinstance.py:1937} ERROR - Task failed with exception
Traceback (most recent call last):
  File "/home/airflow/.local/lib/python3.8/site-packages/airflow/providers/docker/operators/docker.py", line 513, in execute
    return self._run_image()
  File "/home/airflow/.local/lib/python3.8/site-packages/airflow/providers/docker/operators/docker.py", line 384, in _run_image
    return self._run_image_with_mounts(self.mounts, add_tmp_variable=False)
  File "/home/airflow/.local/lib/python3.8/site-packages/airflow/providers/docker/operators/docker.py", line 446, in _run_image_with_mounts
    raise DockerContainerFailedException(f"Docker container failed: {result!r}", logs=log_lines)
airflow.providers.docker.exceptions.DockerContainerFailedException: Docker container failed: {'StatusCode': 1}
[2025-03-02T10:24:31.088+0000] {taskinstance.py:1400} INFO - Marking task as FAILED. dag_id=new_messages, task_id=lda_model, execution_date=20250302T101642, start_date=20250302T102418, end_date=20250302T102431
[2025-03-02T10:24:31.128+0000] {standard_task_runner.py:104} ERROR - Failed to execute job 41 for task lda_model (Docker container failed: {'StatusCode': 1}; 4459)
[2025-03-02T10:24:31.151+0000] {local_task_job_runner.py:228} INFO - Task exited with return code 1
[2025-03-02T10:24:31.194+0000] {taskinstance.py:2778} INFO - 0 downstream tasks scheduled from follow-on schedule check
