[2025-03-01T18:40:39.134+0000] {taskinstance.py:1159} INFO - Dependencies all met for dep_context=non-requeueable deps ti=<TaskInstance: new_messages.messages_load manual__2025-03-01T18:40:33.476902+00:00 [queued]>
[2025-03-01T18:40:39.150+0000] {taskinstance.py:1159} INFO - Dependencies all met for dep_context=requeueable deps ti=<TaskInstance: new_messages.messages_load manual__2025-03-01T18:40:33.476902+00:00 [queued]>
[2025-03-01T18:40:39.151+0000] {taskinstance.py:1361} INFO - Starting attempt 1 of 1
[2025-03-01T18:40:39.176+0000] {taskinstance.py:1382} INFO - Executing <Task(DockerOperator): messages_load> on 2025-03-01 18:40:33.476902+00:00
[2025-03-01T18:40:39.185+0000] {standard_task_runner.py:57} INFO - Started process 9318 to run task
[2025-03-01T18:40:39.191+0000] {standard_task_runner.py:84} INFO - Running: ['***', 'tasks', 'run', 'new_messages', 'messages_load', 'manual__2025-03-01T18:40:33.476902+00:00', '--job-id', '6', '--raw', '--subdir', 'DAGS_FOLDER/mess_cluster.py', '--cfg-path', '/tmp/tmp0q8uyajp']
[2025-03-01T18:40:39.196+0000] {standard_task_runner.py:85} INFO - Job 6: Subtask messages_load
[2025-03-01T18:40:39.298+0000] {task_command.py:416} INFO - Running <TaskInstance: new_messages.messages_load manual__2025-03-01T18:40:33.476902+00:00 [running]> on host a0aaa5637f9f
[2025-03-01T18:40:39.479+0000] {taskinstance.py:1662} INFO - Exporting env vars: AIRFLOW_CTX_DAG_OWNER='***' AIRFLOW_CTX_DAG_ID='new_messages' AIRFLOW_CTX_TASK_ID='messages_load' AIRFLOW_CTX_EXECUTION_DATE='2025-03-01T18:40:33.476902+00:00' AIRFLOW_CTX_TRY_NUMBER='1' AIRFLOW_CTX_DAG_RUN_ID='manual__2025-03-01T18:40:33.476902+00:00'
[2025-03-01T18:40:39.657+0000] {docker.py:367} INFO - Starting docker container from image messages-loader:latest
[2025-03-01T18:42:30.523+0000] {docker.py:438} INFO - Traceback (most recent call last):
[2025-03-01T18:42:30.581+0000] {docker.py:438} INFO -   File "/workdir/Parsing.py", line 53, in <module>
[2025-03-01T18:42:30.584+0000] {docker.py:438} INFO - driver = webdriver.Chrome(options=chrome_options)
[2025-03-01T18:42:30.587+0000] {docker.py:438} INFO - ^^^^^^^^^^^^^^^^^^^^^^^^^^^^^^^^^^^^^^^^
[2025-03-01T18:42:30.588+0000] {docker.py:438} INFO -   File "/usr/local/lib/python3.12/site-packages/selenium/webdriver/chrome/webdriver.py", line 45, in __init__
[2025-03-01T18:42:30.590+0000] {docker.py:438} INFO - super().__init__(
[2025-03-01T18:42:30.590+0000] {docker.py:438} INFO -   File "/usr/local/lib/python3.12/site-packages/selenium/webdriver/chromium/webdriver.py", line 55, in __init__
[2025-03-01T18:42:30.594+0000] {docker.py:438} INFO - self.service.start()
[2025-03-01T18:42:30.595+0000] {docker.py:438} INFO - File "/usr/local/lib/python3.12/site-packages/selenium/webdriver/common/service.py", line 109, in start
[2025-03-01T18:42:30.596+0000] {docker.py:438} INFO - self._start_process(self._path)
[2025-03-01T18:42:30.598+0000] {docker.py:438} INFO - File "/usr/local/lib/python3.12/site-packages/selenium/webdriver/common/service.py", line 219, in _start_process
[2025-03-01T18:42:30.599+0000] {docker.py:438} INFO - self.process = subprocess.Popen(
[2025-03-01T18:42:30.601+0000] {docker.py:438} INFO -                    ^^^^^^^^^^^^^^^^^
[2025-03-01T18:42:30.602+0000] {docker.py:438} INFO -   File "/usr/local/lib/python3.12/subprocess.py", line 1028, in __init__
[2025-03-01T18:42:30.603+0000] {docker.py:438} INFO - self._execute_child(args, executable, preexec_fn, close_fds,
[2025-03-01T18:42:30.605+0000] {docker.py:438} INFO - File "/usr/local/lib/python3.12/subprocess.py", line 1963, in _execute_child
[2025-03-01T18:42:30.606+0000] {docker.py:438} INFO - raise child_exception_type(errno_num, err_msg, err_filename)
[2025-03-01T18:42:30.606+0000] {docker.py:438} INFO - FileNotFoundError: [Errno 2] No such file or directory: '/root/.cache/selenium/chromedriver/linux64/133.0.6943.141/chromedriver'
[2025-03-01T18:42:32.266+0000] {taskinstance.py:1937} ERROR - Task failed with exception
Traceback (most recent call last):
  File "/home/airflow/.local/lib/python3.8/site-packages/airflow/providers/docker/operators/docker.py", line 513, in execute
    return self._run_image()
  File "/home/airflow/.local/lib/python3.8/site-packages/airflow/providers/docker/operators/docker.py", line 384, in _run_image
    return self._run_image_with_mounts(self.mounts, add_tmp_variable=False)
  File "/home/airflow/.local/lib/python3.8/site-packages/airflow/providers/docker/operators/docker.py", line 446, in _run_image_with_mounts
    raise DockerContainerFailedException(f"Docker container failed: {result!r}", logs=log_lines)
airflow.providers.docker.exceptions.DockerContainerFailedException: Docker container failed: {'StatusCode': 1}
[2025-03-01T18:42:32.291+0000] {taskinstance.py:1400} INFO - Marking task as FAILED. dag_id=new_messages, task_id=messages_load, execution_date=20250301T184033, start_date=20250301T184039, end_date=20250301T184232
[2025-03-01T18:42:32.419+0000] {standard_task_runner.py:104} ERROR - Failed to execute job 6 for task messages_load (Docker container failed: {'StatusCode': 1}; 9318)
[2025-03-01T18:42:32.462+0000] {local_task_job_runner.py:228} INFO - Task exited with return code 1
[2025-03-01T18:42:32.600+0000] {taskinstance.py:2778} INFO - 0 downstream tasks scheduled from follow-on schedule check
