[2025-03-01T18:33:06.033+0000] {taskinstance.py:1159} INFO - Dependencies all met for dep_context=non-requeueable deps ti=<TaskInstance: new_messages.messages_load manual__2025-03-01T18:32:57.085960+00:00 [queued]>
[2025-03-01T18:33:06.047+0000] {taskinstance.py:1159} INFO - Dependencies all met for dep_context=requeueable deps ti=<TaskInstance: new_messages.messages_load manual__2025-03-01T18:32:57.085960+00:00 [queued]>
[2025-03-01T18:33:06.048+0000] {taskinstance.py:1361} INFO - Starting attempt 1 of 1
[2025-03-01T18:33:06.076+0000] {taskinstance.py:1382} INFO - Executing <Task(DockerOperator): messages_load> on 2025-03-01 18:32:57.085960+00:00
[2025-03-01T18:33:06.085+0000] {standard_task_runner.py:57} INFO - Started process 5938 to run task
[2025-03-01T18:33:06.096+0000] {standard_task_runner.py:84} INFO - Running: ['***', 'tasks', 'run', 'new_messages', 'messages_load', 'manual__2025-03-01T18:32:57.085960+00:00', '--job-id', '5', '--raw', '--subdir', 'DAGS_FOLDER/mess_cluster.py', '--cfg-path', '/tmp/tmpy8yw65sf']
[2025-03-01T18:33:06.101+0000] {standard_task_runner.py:85} INFO - Job 5: Subtask messages_load
[2025-03-01T18:33:06.196+0000] {task_command.py:416} INFO - Running <TaskInstance: new_messages.messages_load manual__2025-03-01T18:32:57.085960+00:00 [running]> on host a0aaa5637f9f
[2025-03-01T18:33:06.405+0000] {taskinstance.py:1662} INFO - Exporting env vars: AIRFLOW_CTX_DAG_OWNER='***' AIRFLOW_CTX_DAG_ID='new_messages' AIRFLOW_CTX_TASK_ID='messages_load' AIRFLOW_CTX_EXECUTION_DATE='2025-03-01T18:32:57.085960+00:00' AIRFLOW_CTX_TRY_NUMBER='1' AIRFLOW_CTX_DAG_RUN_ID='manual__2025-03-01T18:32:57.085960+00:00'
[2025-03-01T18:33:06.530+0000] {docker.py:367} INFO - Starting docker container from image messages-loader:latest
[2025-03-01T18:33:06.584+0000] {taskinstance.py:1937} ERROR - Task failed with exception
Traceback (most recent call last):
  File "/home/airflow/.local/lib/python3.8/site-packages/docker/api/client.py", line 275, in _raise_for_status
    response.raise_for_status()
  File "/home/airflow/.local/lib/python3.8/site-packages/requests/models.py", line 1021, in raise_for_status
    raise HTTPError(http_error_msg, response=self)
requests.exceptions.HTTPError: 400 Client Error: Bad Request for url: http+docker://localhost/v1.47/containers/create?name=task__messages__load

The above exception was the direct cause of the following exception:

Traceback (most recent call last):
  File "/home/airflow/.local/lib/python3.8/site-packages/airflow/providers/docker/operators/docker.py", line 513, in execute
    return self._run_image()
  File "/home/airflow/.local/lib/python3.8/site-packages/airflow/providers/docker/operators/docker.py", line 384, in _run_image
    return self._run_image_with_mounts(self.mounts, add_tmp_variable=False)
  File "/home/airflow/.local/lib/python3.8/site-packages/airflow/providers/docker/operators/docker.py", line 399, in _run_image_with_mounts
    self.container = self.cli.create_container(
  File "/home/airflow/.local/lib/python3.8/site-packages/docker/api/container.py", line 440, in create_container
    return self.create_container_from_config(config, name, platform)
  File "/home/airflow/.local/lib/python3.8/site-packages/docker/api/container.py", line 457, in create_container_from_config
    return self._result(res, True)
  File "/home/airflow/.local/lib/python3.8/site-packages/docker/api/client.py", line 281, in _result
    self._raise_for_status(response)
  File "/home/airflow/.local/lib/python3.8/site-packages/docker/api/client.py", line 277, in _raise_for_status
    raise create_api_error_from_http_exception(e) from e
  File "/home/airflow/.local/lib/python3.8/site-packages/docker/errors.py", line 39, in create_api_error_from_http_exception
    raise cls(e, response=response, explanation=explanation) from e
docker.errors.APIError: 400 Client Error for http+docker://localhost/v1.47/containers/create?name=task__messages__load: Bad Request ("invalid mount config for type "bind": invalid mount path: '<path_to_your_airflow_ml_repo>/data' mount path must be absolute")
[2025-03-01T18:33:06.610+0000] {taskinstance.py:1400} INFO - Marking task as FAILED. dag_id=new_messages, task_id=messages_load, execution_date=20250301T183257, start_date=20250301T183306, end_date=20250301T183306
[2025-03-01T18:33:06.637+0000] {standard_task_runner.py:104} ERROR - Failed to execute job 5 for task messages_load (400 Client Error for http+docker://localhost/v1.47/containers/create?name=task__messages__load: Bad Request ("invalid mount config for type "bind": invalid mount path: '<path_to_your_airflow_ml_repo>/data' mount path must be absolute"); 5938)
[2025-03-01T18:33:06.685+0000] {local_task_job_runner.py:228} INFO - Task exited with return code 1
[2025-03-01T18:33:06.739+0000] {taskinstance.py:2778} INFO - 0 downstream tasks scheduled from follow-on schedule check
